01.04.2022 20:00:57 ERROR: 421 Cannot connect to SMTP server 172.16.13.30 (172.16.13.30:25), connect error 10060
Traceback (most recent call last):
  File "C:\IT\GitRepo\myCVEs\src\mail.py", line 95, in create_connection
    await server.connect()
  File "C:\IT\GitRepo\myCVEs\.venv\lib\site-packages\aiosmtplib\connection.py", line 314, in connect
    raise exc
  File "C:\IT\GitRepo\myCVEs\.venv\lib\site-packages\aiosmtplib\connection.py", line 311, in connect
    response = await self._create_connection()
  File "C:\IT\GitRepo\myCVEs\.venv\lib\site-packages\aiosmtplib\connection.py", line 397, in _create_connection
    raise SMTPConnectError(str(response))
aiosmtplib.errors.SMTPConnectError: 421 Cannot connect to SMTP server 172.16.13.30 (172.16.13.30:25), connect error 10060
01.04.2022 20:00:57 WARNING: Retrying create_connection for 1. time. Catched error:SMTP connection error 
01.04.2022 20:01:19 ERROR: 421 Cannot connect to SMTP server 172.16.13.30 (172.16.13.30:25), connect error 10060
Traceback (most recent call last):
  File "C:\IT\GitRepo\myCVEs\src\mail.py", line 95, in create_connection
    await server.connect()
  File "C:\IT\GitRepo\myCVEs\.venv\lib\site-packages\aiosmtplib\connection.py", line 314, in connect
    raise exc
  File "C:\IT\GitRepo\myCVEs\.venv\lib\site-packages\aiosmtplib\connection.py", line 311, in connect
    response = await self._create_connection()
  File "C:\IT\GitRepo\myCVEs\.venv\lib\site-packages\aiosmtplib\connection.py", line 397, in _create_connection
    raise SMTPConnectError(str(response))
aiosmtplib.errors.SMTPConnectError: 421 Cannot connect to SMTP server 172.16.13.30 (172.16.13.30:25), connect error 10060
01.04.2022 20:01:19 WARNING: Retrying create_connection for 2. time. Catched error:SMTP connection error 
01.04.2022 20:01:26 ERROR: 421 Cannot connect to SMTP server 172.16.13.30 (172.16.13.30:25), connect error 10061
Traceback (most recent call last):
  File "C:\IT\GitRepo\myCVEs\src\mail.py", line 95, in create_connection
    await server.connect()
  File "C:\IT\GitRepo\myCVEs\.venv\lib\site-packages\aiosmtplib\connection.py", line 314, in connect
    raise exc
  File "C:\IT\GitRepo\myCVEs\.venv\lib\site-packages\aiosmtplib\connection.py", line 311, in connect
    response = await self._create_connection()
  File "C:\IT\GitRepo\myCVEs\.venv\lib\site-packages\aiosmtplib\connection.py", line 397, in _create_connection
    raise SMTPConnectError(str(response))
aiosmtplib.errors.SMTPConnectError: 421 Cannot connect to SMTP server 172.16.13.30 (172.16.13.30:25), connect error 10061
01.04.2022 20:01:26 WARNING: Retrying create_connection for 3. time. Catched error:SMTP connection error 
02.04.2022 10:14:53 ERROR: 421 Cannot connect to SMTP server 172.16.13.30 (172.16.13.30:25), connect error 10060
Traceback (most recent call last):
  File "C:\IT\GitRepo\myCVEs\src\mail.py", line 95, in create_connection
    await server.connect()
  File "C:\IT\GitRepo\myCVEs\.venv\lib\site-packages\aiosmtplib\connection.py", line 314, in connect
    raise exc
  File "C:\IT\GitRepo\myCVEs\.venv\lib\site-packages\aiosmtplib\connection.py", line 311, in connect
    response = await self._create_connection()
  File "C:\IT\GitRepo\myCVEs\.venv\lib\site-packages\aiosmtplib\connection.py", line 397, in _create_connection
    raise SMTPConnectError(str(response))
aiosmtplib.errors.SMTPConnectError: 421 Cannot connect to SMTP server 172.16.13.30 (172.16.13.30:25), connect error 10060
02.04.2022 10:14:53 WARNING: Retrying create_connection for 1. time. Catched error:SMTP connection error 
02.04.2022 10:15:04 ERROR: 421 Cannot connect to SMTP server 172.16.13.30 (172.16.13.30:25), connect error 10061
Traceback (most recent call last):
  File "C:\IT\GitRepo\myCVEs\src\mail.py", line 95, in create_connection
    await server.connect()
  File "C:\IT\GitRepo\myCVEs\.venv\lib\site-packages\aiosmtplib\connection.py", line 314, in connect
    raise exc
  File "C:\IT\GitRepo\myCVEs\.venv\lib\site-packages\aiosmtplib\connection.py", line 311, in connect
    response = await self._create_connection()
  File "C:\IT\GitRepo\myCVEs\.venv\lib\site-packages\aiosmtplib\connection.py", line 397, in _create_connection
    raise SMTPConnectError(str(response))
aiosmtplib.errors.SMTPConnectError: 421 Cannot connect to SMTP server 172.16.13.30 (172.16.13.30:25), connect error 10061
02.04.2022 10:15:04 WARNING: Retrying create_connection for 2. time. Catched error:SMTP connection error 
02.04.2022 10:29:30 WARNING: Retrying make_api_request for 1. time. Catched error: 
02.04.2022 10:29:30 WARNING: Retrying make_api_request for 1. time. Catched error: 
03.04.2022 12:12:54 INFO: Successfull sent new cves
03.04.2022 12:15:47 INFO: Successfull sent new cves
03.04.2022 12:16:21 INFO: Successfull sent new cves
03.04.2022 12:18:31 INFO: Successfull sent new cves
03.04.2022 12:19:22 INFO: Successfull sent new cves
03.04.2022 12:19:46 INFO: Successfull sent new cves
03.04.2022 12:21:05 INFO: Successfull sent new cves
03.04.2022 12:22:21 INFO: Successfull sent new cves
03.04.2022 12:32:00 INFO: Successfull sent new cves
03.04.2022 12:33:45 INFO: Successfull sent new cves
03.04.2022 12:47:11 INFO: Successfull sent new cves
03.04.2022 12:49:28 INFO: Successfull sent new cves
03.04.2022 12:50:41 INFO: Successfull sent new cves
03.04.2022 12:52:43 INFO: Successfull sent new cves
03.04.2022 12:56:09 INFO: Successfull sent new cves
03.04.2022 12:56:30 INFO: Successfull sent new cves
03.04.2022 13:00:18 INFO: Successfull sent new cves
03.04.2022 13:01:16 INFO: Successfull sent new cves
03.04.2022 13:02:59 INFO: Successfull sent new cves
03.04.2022 13:23:16 INFO: Successfull sent all new cves
03.04.2022 13:25:21 INFO: Successfull sent all new cves
03.04.2022 13:26:09 INFO: Successfull sent all new cves
03.04.2022 13:27:35 INFO: Successfull sent all new cves
03.04.2022 13:29:35 INFO: Successfull sent all new cves
03.04.2022 13:30:51 INFO: Successfull sent all new cves
03.04.2022 13:31:48 INFO: Successfull sent all new cves
03.04.2022 13:33:04 INFO: Successfull sent all new cves
03.04.2022 13:35:01 INFO: Successfull sent all new cves
03.04.2022 13:35:38 INFO: Successfull sent all new cves
03.04.2022 13:37:23 INFO: Successfull sent all new cves
03.04.2022 13:41:22 INFO: Successfull sent all new cves
03.04.2022 13:47:48 INFO: Successfull sent all new cves
03.04.2022 13:50:16 INFO: Successfull sent all new cves
03.04.2022 13:52:47 INFO: Successfull sent all new cves
03.04.2022 14:01:34 INFO: Successfull sent all new cves
03.04.2022 14:03:19 INFO: Successfull sent all new cves
03.04.2022 14:06:11 INFO: Successfull sent all new cves
03.04.2022 14:07:14 INFO: Successfull sent all new cves
03.04.2022 14:10:04 INFO: Successfull sent all new cves
03.04.2022 14:11:34 INFO: Successfull sent all new cves
03.04.2022 14:13:22 INFO: Successfull sent all new cves
03.04.2022 14:14:40 INFO: Successfull sent all new cves
03.04.2022 14:15:40 INFO: Successfull sent all new cves
03.04.2022 14:17:32 INFO: Successfull sent all new cves
03.04.2022 14:18:50 INFO: Successfull sent all new cves
03.04.2022 14:19:28 INFO: Successfull sent all new cves
03.04.2022 14:20:08 INFO: Successfull sent all new cves
03.04.2022 14:24:39 INFO: Successfull sent all new cves
03.04.2022 14:26:02 INFO: Successfull sent all new cves
03.04.2022 14:31:38 INFO: Successfull sent all new cves
03.04.2022 14:32:19 WARNING: Retrying make_api_request for 1. time. Catched error: 
03.04.2022 14:32:20 WARNING: Retrying make_api_request for 1. time. Catched error: 
03.04.2022 14:32:26 INFO: Successfull sent all new cves
03.04.2022 14:36:38 INFO: Successfull sent all new cves
03.04.2022 14:37:18 INFO: Successfull sent all new cves
03.04.2022 15:13:22 ERROR: while scanning a simple key
  in "C:\IT\GitRepo\myCVEs\jobs\fortinet.yaml", line 26, column 3
could not find expected ':'
  in "C:\IT\GitRepo\myCVEs\jobs\fortinet.yaml", line 27, column 1
Traceback (most recent call last):
  File "C:\IT\GitRepo\myCVEs\src\jobs_.py", line 37, in get_jobs
    jobs = yaml.safe_load(config)
  File "C:\IT\GitRepo\myCVEs\.venv\lib\site-packages\yaml\__init__.py", line 125, in safe_load
    return load(stream, SafeLoader)
  File "C:\IT\GitRepo\myCVEs\.venv\lib\site-packages\yaml\__init__.py", line 81, in load
    return loader.get_single_data()
  File "C:\IT\GitRepo\myCVEs\.venv\lib\site-packages\yaml\constructor.py", line 49, in get_single_data
    node = self.get_single_node()
  File "C:\IT\GitRepo\myCVEs\.venv\lib\site-packages\yaml\composer.py", line 36, in get_single_node
    document = self.compose_document()
  File "C:\IT\GitRepo\myCVEs\.venv\lib\site-packages\yaml\composer.py", line 55, in compose_document
    node = self.compose_node(None, None)
  File "C:\IT\GitRepo\myCVEs\.venv\lib\site-packages\yaml\composer.py", line 84, in compose_node
    node = self.compose_mapping_node(anchor)
  File "C:\IT\GitRepo\myCVEs\.venv\lib\site-packages\yaml\composer.py", line 133, in compose_mapping_node
    item_value = self.compose_node(node, item_key)
  File "C:\IT\GitRepo\myCVEs\.venv\lib\site-packages\yaml\composer.py", line 82, in compose_node
    node = self.compose_sequence_node(anchor)
  File "C:\IT\GitRepo\myCVEs\.venv\lib\site-packages\yaml\composer.py", line 111, in compose_sequence_node
    node.value.append(self.compose_node(node, index))
  File "C:\IT\GitRepo\myCVEs\.venv\lib\site-packages\yaml\composer.py", line 84, in compose_node
    node = self.compose_mapping_node(anchor)
  File "C:\IT\GitRepo\myCVEs\.venv\lib\site-packages\yaml\composer.py", line 133, in compose_mapping_node
    item_value = self.compose_node(node, item_key)
  File "C:\IT\GitRepo\myCVEs\.venv\lib\site-packages\yaml\composer.py", line 84, in compose_node
    node = self.compose_mapping_node(anchor)
  File "C:\IT\GitRepo\myCVEs\.venv\lib\site-packages\yaml\composer.py", line 127, in compose_mapping_node
    while not self.check_event(MappingEndEvent):
  File "C:\IT\GitRepo\myCVEs\.venv\lib\site-packages\yaml\parser.py", line 98, in check_event
    self.current_event = self.state()
  File "C:\IT\GitRepo\myCVEs\.venv\lib\site-packages\yaml\parser.py", line 428, in parse_block_mapping_key
    if self.check_token(KeyToken):
  File "C:\IT\GitRepo\myCVEs\.venv\lib\site-packages\yaml\scanner.py", line 115, in check_token
    while self.need_more_tokens():
  File "C:\IT\GitRepo\myCVEs\.venv\lib\site-packages\yaml\scanner.py", line 152, in need_more_tokens
    self.stale_possible_simple_keys()
  File "C:\IT\GitRepo\myCVEs\.venv\lib\site-packages\yaml\scanner.py", line 291, in stale_possible_simple_keys
    raise ScannerError("while scanning a simple key", key.mark,
yaml.scanner.ScannerError: while scanning a simple key
  in "C:\IT\GitRepo\myCVEs\jobs\fortinet.yaml", line 26, column 3
could not find expected ':'
  in "C:\IT\GitRepo\myCVEs\jobs\fortinet.yaml", line 27, column 1
03.04.2022 15:13:22 ERROR: Skipping file C:\IT\GitRepo\myCVEs\jobs\fortinet.yaml
03.04.2022 15:13:27 INFO: Successfull sent all new cves
